Workbook
Name __Anonymous_Sheet_DB__1: #REF!
Name __Anonymous_Sheet_DB__1: #REF!
Name __Anonymous_Sheet_DB__1_1: #REF!
Name __Anonymous_Sheet_DB__1_1: #REF!
Name __Anonymous_Sheet_DB__1_2: '[1]Lista de Instrumentos'!#REF!
Name __Anonymous_Sheet_DB__1_2: #REF!
Name __Anonymous_Sheet_DB__1_2: #REF!
Name __Anonymous_Sheet_DB__1_3: #REF!
Name __Anonymous_Sheet_DB__1_3: #REF!
Name Excel_BuiltIn__FilterDatabase_1: #REF!
Name Excel_BuiltIn__FilterDatabase_1: #REF!
Name Excel_BuiltIn__FilterDatabase_2: '[1]Lista de Instrumentos'!#REF!
Name Excel_BuiltIn__FilterDatabase_2: #REF!
Name Excel_BuiltIn__FilterDatabase_2_1: '[1]Lista de Instrumentos'!#REF!
Name Excel_BuiltIn__FilterDatabase_2_1: #REF!

Sheet CAPA
A1: REVISÕES
A2: Nº | B2: DESCRIÇÃO | G2: TIPO | I2: PROJETADO | M2: VERIFICADO | N2: APROVADO | P2: DATA
A5: 5 | B5: CONFORME DOCUMENTOS RECEBIDOS (INDICADO DE MARROM) | G5: B | I5: JKP | M5: AM | N5: GBA | P5: 45946
A6: 4 | B6: CONFORME DOCUMENTOS RECEBIDOS (INDICADO DE AZUL) | G6: B | I6: JKP | M6: AM | N6: GBA | P6: 45814
A7: 3 | B7: CONFORME DOCUMENTOS RECEBIDOS (INDICADO DE AMARELO) | G7: B | I7: JKP | M7: AM | N7: GBA | P7: 45798
A8: 2 | B8: PARA APROVAÇÃO | G8: B | I8: JKP | M8: AM | N8: GBA | P8: 45763
A9: 1 | B9: ATENDENDO COMENTÁRIOS | G9: B | I9: JKP | M9: AM | N9: GBA | P9: 45755
A10: 0 | B10: EMISSÃO INICIAL | G10: B | I10: JKP | M10: AM | N10: GBA | P10: 45677
A11: TIPO DE EMISSÃO
A12: (A) PRELIMINAR | F12: (D) PARA CONSTRUÇÃO | L12: (G) CANCELADO
A13: (B) PARA APROVAÇÃO | F13: (E) CONFORME CONSTRUÍDO | L13: (H) PARA COTAÇÃO
A14: (C) PARA CONHECIMENTO | F14: (F) APROVADO | L14: (I) CONFORME COMPRADO
K17: Nº DOC:
K19: LI-A-20V093E-001
K23: DATA: | Q23: REV.
K24: =LARGE(P3:Q10,1) -> 45946 | Q24: =LARGE(A3:A10,1) -> 5
G27: VOTORANTIM CIMENTOS FÁBRICA DE EDEALINA - GO
A28: TÍTULO DO DOCUMENTO:
A30: VOTORANTIM CIMENTOS
A31: FÁBRICA DE EDEALINA - GO PROJETO DETALHADO - MOAGEM DE CIMENTO Z2
A33: LISTA DE INSTRUMENTOS
A37: DATA: | D37: APROVADO POR: | J37: Nº CLIENTE: | O37: REVISÃO:
A38: =K24 -> 45946 | D38: VICTOR MENDONÇA | J38: ED-I-Z2000-120 | O38: =Q24 -> 5

Sheet ADITIVOS
H1: CLIENTE: | I1: =CAPA!G27 -> VOTORANTIM CIMENTOS FÁBRICA DE EDEALINA - GO | M1: PROJETO: | N1: =CAPA!A31 -> FÁBRICA DE EDEALINA - GO PROJETO DETALHADO - MOAGEM DE CIMENTO Z2 | Q1: VERIFICADO: | R1: ALEXANDRE MANDUCA
Q2: APROVADO: | R2: GIANCARLO BORGES AVELAR
H3: TÍTULO: | I3: LISTA DE INSTRUMENTO ADITIVOS | M3: Nº. CLIENTE: | N3: =CAPA!J38 -> ED-I-Z2000-120 | Q3: FOLHA: | R3: REVISÃO: | S3: =CAPA!Q24 -> 5
M4: Nº. SM&A: | N4: =CAPA!K19 -> LI-A-20V093E-001 | R4: DATA: | S4: =CAPA!K24 -> 45946
A5: ITEM | B5: TAG VC | C5: TAG SINOMA | D5: EQUIPAMENTO | E5: FUNÇÃO | F5: INSTRUMENTO | G5: TIPO DE SINAL | H5: RANGE MÍNIMO | I5: RANGE MÁXIMO | J5: FABRICANTE | K5: MODELO | L5: QT | M5: FORNECEDOR | N5: PAINEL PARA INTERLIGAÇÃO | O5: MATERIAL PARA MONTAGEM | P5: FOLHA DE DADOS | Q5: COMENTÁRIOS | S5: REV.
A6: 1 | B6: G1L03XV1 | C6: 551AC01 | D6: SILO DE GESSO - G1L03 CANHÃO DE AR #1 | E6: COMANDO ABRE / FECHA | F6: VÁLVULA SOLENOIDE | G6: 120Vca | H6: - | I6: - | J6: ASCO | K6: SCG353G051 | L6: 1 | M6: SINOMA | N6: Z2RM6 | O6: - | P6: - | Q6: - | S6: 1
A7: =A6+1 -> 2 | B7: G1L03XV2 | C7: 551AC02 | D7: SILO DE GESSO - G1L03 CANHÃO DE AR #2 | E7: COMANDO ABRE / FECHA | F7: VÁLVULA SOLENOIDE | G7: 120Vca | H7: - | I7: - | J7: ASCO | K7: SCG353G051 | L7: 1 | M7: SINOMA | N7: Z2RM6 | O7: - | P7: - | Q7: - | S7: 1
A8: =A7+1 -> 3 | B8: G1L03XV3 | C8: 551AC03 | D8: SILO DE GESSO - G1L03 CANHÃO DE AR #3 | E8: COMANDO ABRE / FECHA | F8: VÁLVULA SOLENOIDE | G8: 120Vca | H8: - | I8: - | J8: ASCO | K8: SCG353G051 | L8: 1 | M8: SINOMA | N8: Z2RM6 | O8: - | P8: - | Q8: - | S8: 1
A9: =A8+1 -> 4 | B9: G1L03XV4 | C9: 551AC04 | D9: SILO DE GESSO - G1L03 CANHÃO DE AR #4 | E9: COMANDO ABRE / FECHA | F9: VÁLVULA SOLENOIDE | G9: 120Vca | H9: - | I9: - | J9: ASCO | K9: SCG353G051 | L9: 1 | M9: SINOMA | N9: Z2RM6 | O9: - | P9: - | Q9: - | S9: 1
A10: =A9+1 -> 5 | B10: Z2A01FSL | C10: - | D10: BALANÇA DOSADORA DE CLINQUER - Z2A01 | E10: FLUXO BAIXO | F10: SENSOR INDUTIVO DE PROXIMIDADE | G10: 120Vca | H10: - | I10: - | J10: TELEMECANIQUE | K10: XS1M30MB250 | L10: 1 | M10: VOTORANTIM | N10: Z2RM6 | O10: - | P10: ED-I-Z2000-103 | Q10: - | S10: 1
A11: =A10+1 -> 6 | B11: Z2A01Q1 | C11: 551AW01.FZ1 | D11: BALANÇA DOSADORA DE CLINQUER - Z2A01 | E11: PAINEL DA BALANÇA DOSADORA | F11: PAINEL LOCAL | G11: 120Vca | H11: - | I11: - | J11: SCHENCK | K11: VEG 20650/VWF20650 | L11: 1 | M11: SINOMA | N11: Z2RM6 | O11: - | P11: - | Q11: - | S11: 1
A12: =A11+1 -> 7 | B12: Z2B01FSL | C12: - | D12: BALANÇA DOSADORA DE GESSO - Z2B01 | E12: FLUXO BAIXO | F12: SENSOR INDUTIVO DE PROXIMIDADE | G12: 120Vca | H12: - | I12: - | J12: TELEMECANIQUE | K12: XS1M30MB250 | L12: 1 | M12: VOTORANTIM | N12: Z2RM6 | O12: - | P12: ED-I-Z2000-103 | Q12: - | S12: 1
A13: =A12+1 -> 8 | B13: Z2B01Q1 | C13: 551WF02.FZ1 | D13: BALANÇA DOSADORA DE GESSO - Z2B01 | E13: PAINEL DA BALANÇA DOSADORA | F13: PAINEL LOCAL | G13: 120Vca | H13: - | I13: - | J13: SCHENCK | K13: VEG 20650/VWF20650 | L13: 1 | M13: SINOMA | N13: Z2RM6 | O13: - | P13: - | Q13: - | S13: 1
A14: =A13+1 -> 9 | B14: Z2C01FSL | C14: - | D14: BALANÇA DOSADORA DE CALCÁRIO - Z2C01 | E14: FLUXO BAIXO | F14: SENSOR INDUTIVO DE PROXIMIDADE | G14: 120Vca | H14: - | I14: - | J14: TELEMECANIQUE | K14: XS1M30MB250 | L14: 1 | M14: VOTORANTIM | N14: Z2RM6 | O14: - | P14: ED-I-Z2000-103 | Q14: - | S14: 1
A15: =A14+1 -> 10 | B15: Z2C01Q1 | C15: 551WF01.FZ1 | D15: BALANÇA DOSADORA DE CALCÁRIO - Z2C01 | E15: PAINEL DA BALANÇA DOSADORA | F15: PAINEL LOCAL | G15: 120Vca | H15: - | I15: - | J15: SCHENCK | K15: VEG 20650/VWF20650 | L15: 1 | M15: SINOMA | N15: Z2RM6 | O15: - | P15: - | Q15: - | S15: 1
A16: =A15+1 -> 11 | B16: Z2D01FSL | C16: - | D16: BALANÇA DOSADORA DE ESCÓRIA - Z2D01 | E16: FLUXO BAIXO | F16: SENSOR INDUTIVO DE PROXIMIDADE | G16: 120Vca | H16: - | I16: - | J16: TELEMECANIQUE | K16: XS1M30MB250 | L16: 1 | M16: VOTORANTIM | N16: Z2RM6 | O16: - | P16: ED-I-Z2000-103 | Q16: - | S16: 1
A17: =A16+1 -> 12 | B17: Z2D01Q1 | C17: 551WF03.FZ1 | D17: BALANÇA DOSADORA DE ESCÓRIA - Z2D01 | E17: PAINEL DA BALANÇA DOSADORA | F17: PAINEL LOCAL | G17: 120Vca | H17: - | I17: - | J17: SCHENCK | K17: VEG 20650/VWF20650 | L17: 1 | M17: SINOMA | N17: Z2RM6 | O17: - | P17: - | Q17: - | S17: 1
A18: =A17+1 -> 13 | B18: Z2J01HS1 | C18: 551BC01.RS1/3 | D18: CORREIA TRANSPORTADORA - Z2J01 | E18: EMERGÊNCIA LADO ESQUERDO | F18: CHAVE DE EMERGÊNCIA DE CORDA | G18: 120Vca | H18: - | I18: - | J18: Schneider | K18: XY2CEDB296 | L18: 2 | M18: SINOMA | N18: Z2RM6 | O18: - | P18: - | Q18: Z2J01HS1.1 / Z2J01HS1.2 | S18: 1
... A41: =A40+1 -> 36 | B41: Z2P11Q1 | C41: 551BF01.UZ1 | D41: FILTRO DE MANGAS - Z2P11 | E41: PROGRAMADOR DO FILTRO DE MANGAS | F41: PAINEL LOCAL | G41: 120Vca | H41: - | I41: - | J41: WALSH | K41: WHPC PULSER CONTROLLER | L41: 1 | M41: SINOMA | N41: Z2RM6 | O41: - | P41: - | Q41: 6x VÁLVULA SOLENOIDE | S41: 1
A42: =A41+1 -> 37 | B42: Z2P11PDT | C42: 551BF01.PZ1 | D42: FILTRO DE MANGAS - Z2P11 | E42: PRESSÃO DIFERENCIAL FILTRO DE MANGAS | F42: TRANSMISSOR DE PRESSÃO DIFERENCIAL | G42: 4-20mA | J42: SIEMENS | K42: 7MF0340-1HM01-5SM2-Z B30+D42+E27 | L42: 1 | M42: SINOMA | N42: Z2RM6 | O42: - | P42: - | Q42: - | S42: 1
A43: =A42+1 -> 38 | B43: Z2P11LSH | C43: 551BF01.LS1 | D43: FILTRO DE MANGAS - Z2P11 | E43: NÍVEL ALTO | F43: CHAVE DE NÍVEL | G43: 120Vca | J43: E+H | K43: FTM21-AG242A | L43: 1 | M43: SINOMA | N43: Z2RM6 | O43: - | P43: - | Q43: - | S43: 1
A44: =A43+1 -> 39 | B44: Z2P13SECX | C44: - | D44: VÁLVULA ROTATIVA - Z2P13 | E44: CAIXA DE PROTEÇÃO PARA VIGIA DE VELOCIDADE | F44: - | G44: - | H44: - | I44: - | J44: - | K44: CX. Padrão Vigia de Velocidade com anteparo de 2 Aletas (30 a 60 rpm) | L44: 1 | M44: VOTORANTIM | N44: - | O44: VCM-0828 IT 02 + VCM-0830 | P44: Código de Compra VC: 491550 | Q44: COMPRAR CONFORME MODELO VOTORANTIM INFORMADO NA COLUNA FOLHA DE DADOS | S44: 1
A45: =A44+1 -> 40 | B45: Z2P13SE | C45: 551RF01.SS1 | D45: VÁLVULA ROTATIVA - Z2P13 | E45: VIGIA DE VELOCIDADE | F45: SENSOR INDUTIVO DE PROXIMIDADE | G45: 120Vca | H45: - | I45: - | J45: SCHNEIDER | K45: TE XSA-V11801 | L45: 1 | M45: SINOMA | N45: Z2RM6 | O45: - | P45: - | Q45: - | S45: 1
A46: =A45+1 -> 41 | B46: Z2P21PSL | C46: 551BF02.PS1 | D46: FILTRO DE MANGAS - Z2P21 | E46: PRESSÃO BAIXA LINHA DE AR | F46: PRESSOSTATO | G46: 120Vca | H46: - | I46: - | J46: SCHNEIDER | K46: XML B010A2S11 | L46: 1 | M46: SINOMA | N46: Z2RM6 | O46: - | P46: - | Q46: - | S46: 1
A47: =A46+1 -> 42 | B47: Z2P21Q1 | C47: 551BF02.UZ1 | D47: FILTRO DE MANGAS - Z2P21 | E47: PROGRAMADOR DO FILTRO DE MANGAS | F47: PAINEL LOCAL | G47: 120Vca | H47: - | I47: - | J47: WALSH | K47: WHPC PULSER CONTROLLER | L47: 1 | M47: SINOMA | N47: Z2RM6 | O47: - | P47: - | Q47: 6x VÁLVULA SOLENOIDE | S47: 1
A48: =A47+1 -> 43 | B48: Z2P21PDT | C48: 551BF02.PZ1 | D48: FILTRO DE MANGAS - Z2P21 | E48: PRESSÃO DIFERENCIAL FILTRO DE MANGAS | F48: TRANSMISSOR DE PRESSÃO DIFERENCIAL | G48: 4-20mA | J48: SIEMENS | K48: 7MF0340-1HM01-5SM2-Z B30+D42+E27 | L48: 1 | M48: SINOMA | N48: Z2RM6 | O48: - | P48: - | Q48: - | S48: 1
A49: =A48+1 -> 44 | B49: Z2P21LSH | C49: 551BF02.LS1 | D49: FILTRO DE MANGAS - Z2P21 | E49: NÍVEL ALTO | F49: CHAVE DE NÍVEL | G49: 120Vca | J49: E+H | K49: FTM21-AG242A | L49: 1 | M49: SINOMA | N49: Z2RM6 | O49: - | P49: - | Q49: - | S49: 1
A50: =A49+1 -> 45 | B50: Z2P23SE | C50: 551RF02.SS1 | D50: VÁLVULA ROTATIVA - Z2P23 | E50: VIGIA DE VELOCIDADE | F50: SENSOR INDUTIVO DE PROXIMIDADE | G50: 120Vca | H50: - | I50: - | J50: SCHNEIDER | K50: TE XSA-V11801 | L50: 1 | M50: SINOMA | N50: Z2RM6 | O50: - | P50: - | Q50: - | S50: 1
A51: =A50+1 -> 46 | B51: Z2P23SECX | C51: - | D51: VÁLVULA ROTATIVA - Z2P23 | E51: CAIXA DE PROTEÇÃO PARA VIGIA DE VELOCIDADE | F51: - | G51: - | H51: - | I51: - | J51: - | K51: CX. Padrão Vigia de Velocidade com anteparo de 2 Aletas (30 a 60 rpm) | L51: 1 | M51: VOTORANTIM | N51: - | O51: VCM-0828 IT 02 + VCM-0830 | P51: Código de Compra VC: 491550 | Q51: COMPRAR CONFORME MODELO VOTORANTIM INFORMADO NA COLUNA FOLHA DE DADOS | S51: 1
A52: =A51+1 -> 47 | B52: Z2S08SE | C52: - | D52: EXTRATOR DE METAIS - Z2S08 | E52: VIGIA DE VELOCIDADE | F52: SENSOR INDUTIVO DE PROXIMIDADE | G52: 120Vca | H52: - | I52: - | J52: TELEMECANIQUE | K52: XS1M30MB250 | L52: 1 | M52: VOTORANTIM | N52: Z2RM2 | O52: - | P52: ED-I-Z2000-103 | Q52: - | S52: 1
A53: =A52+1 -> 48 | B53: Z2S08SECX | C53: - | D53: SISTEMA DE INJEÇÃO DE ÁGUA PARA MOINHO - Z2K01 | E53: CAIXA DE PROTEÇÃO PARA VIGIA DE VELOCIDADE | F53: - | G53: - | H53: - | I53: - | J53: - | K53: CX. Padrão Vigia de Velocidade com anteparo de 2 Aletas (30 a 60 rpm) | L53: 1 | M53: VOTORANTIM | N53: - | O53: VCM-0828 IT 02 + VCM-0830 | P53: Código de Compra VC: 491550 | Q53: COMPRAR CONFORME MODELO VOTORANTIM INFORMADO NA COLUNA FOLHA DE DADOS | S53: 1
A54: =A53+1 -> 49 | B54: Z2SIR01 | C54: - | D54: SIRENE | E54: ALARME | F54: SIRENE | G54: 120Vca | H54: - | I54: - | J54: TUCANO | K54: SR120-120V | L54: 1 | M54: VOTORANTIM | N54: Z2RM6 | O54: - | P54: ED-I-Z2000-108 | Q54: - | S54: 1

Sheet MOAGEM DE CIMENTO
H1: CLIENTE: | I1: =CAPA!G27 -> VOTORANTIM CIMENTOS FÁBRICA DE EDEALINA - GO | M1: PROJETO: | N1: =CAPA!A31 -> FÁBRICA DE EDEALINA - GO PROJETO DETALHADO - MOAGEM DE CIMENTO Z2 | Q1: VERIFICADO: | R1: ALEXANDRE MANDUCA
Q2: APROVADO: | R2: GIANCARLO BORGES AVELAR
H3: TÍTULO: | I3: LISTA DE INSTRUMENTO MOAGEM DE CIMENTO Z2 | M3: Nº. CLIENTE: | N3: =CAPA!J38 -> ED-I-Z2000-120 | Q3: FOLHA: | R3: REVISÃO: | S3: =CAPA!Q24 -> 5
M4: Nº. SM&A: | N4: =CAPA!K19 -> LI-A-20V093E-001 | R4: DATA: | S4: =CAPA!K24 -> 45946
A5: ITEM | B5: TAG VC | C5: TAG SINOMA | D5: EQUIPAMENTO | E5: FUNÇÃO | F5: INSTRUMENTO | G5: TIPO DE SINAL | H5: RANGE MÍNIMO | I5: RANGE MÁXIMO | J5: FABRICANTE | K5: MODELO | L5: QTY | M5: FORNECEDOR | N5: PAINEL PARA INTERLIGAÇÃO | O5: MATERIAL PARA MONTAGEM | P5: FOLHA DE DADOS | Q5: COMENTÁRIOS | S5: REV.
A6: 1 | B6: Z2J08LSH | C6: - | D6: REGUEIRA DE SAÍDA DO MOINHO - Z2J08 | E6: NÍVEL ALTO | F6: CHAVE DE NÍVEL | G6: 120Vca | H6: 150mm | I6: 300mm | J6: VEGA | K6: VEGAVIB63 | L6: 1 | M6: VOTORANTIM | N6: Z2RM5 | O6: - | P6: ED-I-Z2000-107 | Q6: - | S6: 1
A7: =A6+1 -> 2 | B7: Z2J10LSH | C7: 571BE01.LS1 | D7: ELEVADOR DE CANECAS - Z2J10 | E7: NÍVEL ALTO | F7: CHAVE DE NÍVEL | G7: 120Vca | H7: - | I7: - | J7: E+H | K7: FTE20-AA11AA31 | L7: 1 | M7: SINOMA | N7: Z2RM5 | O7: - | P7: - | Q7: - | S7: 1
A8: =A7+1 -> 3 | B8: Z2J10M2SE | C8: 571BE01.M2.SS1 | D8: ELEVADOR DE CANECAS - Z2J10 | E8: SENSOR DO MOTOR AUXILIAR VIGIA DE VELOCIDADE | F8: SENSOR INDUTIVO NAMUR | G8: 120Vca | H8: - | I8: - | J8: IFM | K8: IG5497+ECV004 DD0203 | L8: 1 | M8: SINOMA | N8: Z2RM5 | O8: - | P8: - | Q8: - | S8: 1
A9: =A8+1 -> 4 | B9: Z2J10SE1 | C9: 571BE01.SS1 | D9: ELEVADOR DE CANECAS - Z2J10 | E9: SENSOR 1 - PÉ DO ELEVADOR VIGIA DE VELOCIDADE | F9: SENSOR INDUTIVO DE PROXIMIDADE | G9: 120Vca | H9: - | I9: - | J9: Schneider | K9: XSAV11801 | L9: 1 | M9: SINOMA | N9: Z2RM5 | O9: - | P9: - | Q9: - | S9: 1
A10: =A9+1 -> 5 | B10: Z2J10SE1CX | C10: - | D10: ELEVADOR DE CANECAS - Z2J10 | E10: CAIXA DE PROTEÇÃO PARA VIGIA DE VELOCIDADE | F10: - | G10: - | H10: - | I10: - | J10: - | K10: CX. Padrão Vigia de Velocidade com anteparo de 2 Aletas (30 a 60 rpm) | L10: 1 | M10: VOTORANTIM | N10: - | O10: VCM-0828 IT 02 + VCM-0830 | P10: Código de Compra VC: 491550 | Q10: COMPRAR CONFORME MODELO VOTORANTIM INFORMADO NA COLUNA FOLHA DE DADOS | S10: 1
A11: =A10+1 -> 6 | B11: Z2J10SE2 | C11: - | D11: ELEVADOR DE CANECAS - Z2J10 | E11: SENSOR 2 - PÉ DO ELEVADOR VIGIA DE VELOCIDADE | F11: SENSOR INDUTIVO DE PROXIMIDADE | G11: 120Vca | H11: - | I11: - | J11: TELEMECANIQUE | K11: XS1M30MB250 | L11: 1 | M11: VOTORANTIM | N11: Z2RM5 | O11: - | P11: ED-I-Z2000-103 | Q11: - | S11: 1
A12: =A11+1 -> 7 | B12: Z2J10SE2CX | C12: - | D12: ELEVADOR DE CANECAS - Z2J10 | E12: CAIXA DE PROTEÇÃO PARA VIGIA DE VELOCIDADE | F12: - | G12: - | H12: - | I12: - | J12: - | K12: CX. Padrão Vigia de Velocidade com anteparo de 2 Aletas (30 a 60 rpm) | L12: 1 | M12: VOTORANTIM | N12: - | O12: VCM-0828 IT 02 + VCM-0830 | P12: Código de Compra VC: 491550 | Q12: COMPRAR CONFORME MODELO VOTORANTIM INFORMADO NA COLUNA FOLHA DE DADOS | S12: 1
A13: =A12+1 -> 8 | B13: Z2J10SE3 | C13: - | D13: ELEVADOR DE CANECAS - Z2J10 | E13: SENSOR - TOPO DO ELEVADOR VIGIA DE VELOCIDADE | F13: SENSOR INDUTIVO DE PROXIMIDADE | G13: 120Vca | H13: - | I13: - | J13: TELEMECANIQUE | K13: XS1M30MB250 | L13: 1 | M13: VOTORANTIM | N13: Z2RM5 | O13: - | P13: ED-I-Z2000-103 | Q13: - | S13: 1
A14: =A13+1 -> 9 | B14: Z2J10SE3CX | C14: - | D14: ELEVADOR DE CANECAS - Z2J10 | E14: CAIXA DE PROTEÇÃO PARA VIGIA DE VELOCIDADE | F14: - | G14: - | H14: - | I14: - | J14: - | K14: CX. Padrão Vigia de Velocidade com anteparo de 2 Aletas (30 a 60 rpm) | L14: 1 | M14: VOTORANTIM | N14: - | O14: VCM-0828 IT 02 + VCM-0830 | P14: Código de Compra VC: 491550 | Q14: COMPRAR CONFORME MODELO VOTORANTIM INFORMADO NA COLUNA FOLHA DE DADOS | S14: 1
A15: =A14+1 -> 10 | B15: Z2J10TSH | C15: 571BE01.TS1 | D15: ELEVADOR DE CANECAS - Z2J10 | E15: TEMPERATURA ÓLEO ACOPLAMENTO ELEVADOR Z2J10 | F15: SENSOR TEMPERATURA | G15: 120Vca | H15: - | I15: - | J15: Schneider | K15: XCMD2102L1 | L15: 1 | M15: SINOMA | N15: Z2RM5 | O15: - | P15: - | Q15: - | S15: 1
A16: =A15+1 -> 11 | B16: Z2J10XT1 | C16: - | D16: ELEVADOR DE CANECAS - Z2J10 | E16: VIBRAÇÃO DO MANCAL DO MOTOR | F16: TRANSMISSOR DE VIBRAÇÃO | G16: 4-20 mA | H16: 0 mm/s | I16: 25 mm/s | J16: IFM | K16: VTV122 | L16: 1 | M16: VOTORANTIM | N16: Z2RM5 | O16: - | P16: ED-I-Z2000-106 | Q16: - | S16: 1
A17: =A16+1 -> 12 | B17: Z2J10XT2 | C17: - | D17: ELEVADOR DE CANECAS - Z2J10 | E17: VIBRAÇÃO DO MANCAL DO REDUTOR | F17: TRANSMISSOR DE VIBRAÇÃO | G17: 4-20 mA | H17: 0 mm/s | I17: 25 mm/s | J17: IFM | K17: VTV122 | L17: 1 | M17: VOTORANTIM | N17: Z2RM5 | O17: - | P17: ED-I-Z2000-106 | Q17: - | S17: 1
A18: =A17+1 -> 13 | B18: Z2J10ZSH1 | C18: 571BE01.XS1 | D18: ELEVADOR DE CANECAS - Z2J10 | E18: ESTICAMENTO NO PÉ | F18: SENSOR INDUTIVO DE PROXIMIDADE | G18: 120Vca | H18: - | I18: - | J18: Schneider | K18: XS630B1MAL2 | L18: 1 | M18: SINOMA | N18: Z2RM5 | O18: - | P18: - | Q18: - | S18: 5
A19: =A18+1 -> 14 | B19: Z2J10ZSH2 | C19: 571BE01.XS1 | D19: ELEVADOR DE CANECAS - Z2J10 | E19: ESTICAMENTO NO TOPO | F19: SENSOR INDUTIVO DE PROXIMIDADE | G19: 120Vca | H19: - | I19: - | J19: Schneider | K19: XS630B1MAL2 | L19: 1 | M19: SINOMA | N19: Z2RM5 | O19: - | P19: - | Q19: - | S19: 5
A20: =A19+1 -> 15 | B20: Z2J10M1TE1 | C20: 571BE01.M1.TS1 | D20: TEMPERATURA FASE R - Z2J10 | E20: Motor Winding Temperature | G20: PT100 | J20: SIEMENS | K20: PENDENTE SINOMA | L20: 1 | M20: SINOMA | N20: Z2RM5 | O20: - | P20: - | Q20: - | S20: 5
A21: =A20+1 -> 16 | B21: Z2J10M1TE2 | C21: 571BE01.M1.TS2 | D21: TEMPERATURA FASE S - Z2J10 | E21: Motor Winding Temperature | G21: PT100 | J21: SIEMENS | K21: PENDENTE SINOMA | L21: 1 | M21: SINOMA | N21: Z2RM5 | O21: - | P21: - | Q21: - | S21: 5
A22: =A21+1 -> 17 | B22: Z2J10M1TE3 | C22: 571BE01.M1.TS3 | D22: TEMPERATURA FASE T- Z2J10 | E22: Motor Winding Temperature | G22: PT100 | J22: SIEMENS | K22: PENDENTE SINOMA | L22: 1 | M22: SINOMA | N22: Z2RM5 | O22: - | P22: - | Q22: - | S22: 5
A23: =A22+1 -> 18 | B23: Z2J11LSH | C23: - | D23: REGUEIRA DE SAÍDA DO ELEVADOR DE CANECAS - Z2J11 | E23: NÍVEL ALTO | F23: CHAVE DE NÍVEL | G23: 120Vca | H23: 150mm | I23: 300mm | J23: VEGA | K23: VEGAVIB63 | L23: 1 | M23: VOTORANTIM | N23: Z2RM7 | O23: - | P23: ED-I-Z2000-107 | Q23: - | S23: 1
A24: =A23+1 -> 19 | B24: Z2J16ZSH | C24: - | D24: VÁLVULA DUPLO FLAP - Z2J16 | E24: ABERTO SUPERIOR | F24: SENSOR INDUTIVO DE PROXIMIDADE | G24: 120Vca | H24: - | I24: - | J24: TELEMECANIQUE | K24: XS1M30MB250 | L24: 1 | M24: VOTORANTIM | N24: Z2RM7 | O24: - | P24: ED-I-Z2000-103 | Q24: - | S24: 1
A25: =A24+1 -> 20 | B25: Z2J16ZSL | C25: - | D25: VÁLVULA DUPLO FLAP - Z2J16 | E25: ABERTO INFERIOR | F25: SENSOR INDUTIVO DE PROXIMIDADE | G25: 120Vca | H25: - | I25: - | J25: TELEMECANIQUE | K25: XS1M30MB250 | L25: 1 | M25: VOTORANTIM | N25: Z2RM7 | O25: - | P25: ED-I-Z2000-103 | Q25: - | S25: 1
A26: =A25+1 -> 21 | B26: Z2J18LSH | C26: 571BE02.LS1 | D26: ELEVADOR DE CANECAS - Z2J18 | E26: NÍVEL ALTO | F26: CHAVE DE NÍVEL | G26: 120Vca | H26: - | I26: - | J26: E+H | K26: FTE20-AA11AA31 | L26: 1 | M26: SINOMA | N26: Z2RM7 | O26: - | P26: - | Q26: - | S26: 1
A27: =A26+1 -> 22 | B27: Z2J18M1TSH | C27: 571BE02.TS1 | D27: ELEVADOR DE CANECAS - Z2J18 | E27: TEMPERATURA ÓLEO ACOPLAMENTO ELEVADOR Z2J18 | F27: SENSOR TEMPERATURA | G27: 120Vca | H27: - | I27: - | J27: Schneider | K27: XCMD2102L1 | L27: 1 | M27: SINOMA | N27: Z2RM7 | O27: - | P27: - | Q27: - | S27: 1
A28: =A27+1 -> 23 | B28: Z2J18M2SE | C28: 571BE02.M2.SS1 | D28: ELEVADOR DE CANECAS - Z2J18 | E28: SENSOR DO MOTOR AUXILIAR VIGIA DE VELOCIDADE | F28: SENSOR INDUTIVO NAMUR | G28: 120Vca | H28: - | I28: - | J28: IFM | K28: IG5497+ECV004 DD0203 | L28: 1 | M28: SINOMA | N28: Z2RM7 | O28: - | P28: - | Q28: - | S28: 1
A29: =A28+1 -> 24 | B29: Z2J18SE1 | C29: 571BE02.SS1 | D29: ELEVADOR DE CANECAS - Z2J18 | E29: SENSOR 1 - PÉ DO ELEVADOR VIGIA DE VELOCIDADE | F29: SENSOR INDUTIVO DE PROXIMIDADE | G29: 120Vca | H29: - | I29: - | J29: Schneider | K29: XSAV11801 | L29: 1 | M29: SINOMA | N29: Z2RM7 | O29: - | P29: - | Q29: - | S29: 1
A30: =A29+1 -> 25 | B30: Z2J18SE1CX | C30: - | D30: ELEVADOR DE CANECAS - Z2J18 | E30: CAIXA DE PROTEÇÃO PARA VIGIA DE VELOCIDADE | F30: - | G30: - | H30: - | I30: - | J30: - | K30: CX. Padrão Vigia de Velocidade com anteparo de 2 Aletas (30 a 60 rpm) | L30: 1 | M30: VOTORANTIM | N30: - | O30: VCM-0828 IT 02 + VCM-0830 | P30: Código de Compra VC: 491550 | Q30: COMPRAR CONFORME MODELO VOTORANTIM INFORMADO NA COLUNA FOLHA DE DADOS | S30: 1
A31: =A30+1 -> 26 | B31: Z2J18SE2 | C31: - | D31: ELEVADOR DE CANECAS - Z2J18 | E31: SENSOR 2 - PÉ DO ELEVADOR VIGIA DE VELOCIDADE | F31: SENSOR INDUTIVO DE PROXIMIDADE | G31: 120Vca | H31: - | I31: - | J31: TELEMECANIQUE | K31: XS1M30MB250 | L31: 1 | M31: VOTORANTIM | N31: Z2RM7 | O31: - | P31: ED-I-Z2000-103 | Q31: - | S31: 1
A32: =A31+1 -> 27 | B32: Z2J18SE2CX | C32: - | D32: ELEVADOR DE CANECAS - Z2J18 | E32: CAIXA DE PROTEÇÃO PARA VIGIA DE VELOCIDADE | F32: - | G32: - | H32: - | I32: - | J32: - | K32: CX. Padrão Vigia de Velocidade com anteparo de 2 Aletas (30 a 60 rpm) | L32: 1 | M32: VOTORANTIM | N32: - | O32: VCM-0828 IT 02 + VCM-0830 | P32: Código de Compra VC: 491550 | Q32: COMPRAR CONFORME MODELO VOTORANTIM INFORMADO NA COLUNA FOLHA DE DADOS | S32: 1
A33: =A32+1 -> 28 | B33: Z2J18SE3 | C33: - | D33: ELEVADOR DE CANECAS - Z2J18 | E33: SENSOR - TOPO DO ELEVADOR VIGIA DE VELOCIDADE | F33: SENSOR INDUTIVO DE PROXIMIDADE | G33: 120Vca | H33: - | I33: - | J33: TELEMECANIQUE | K33: XS1M30MB250 | L33: 1 | M33: VOTORANTIM | N33: Z2RM7 | O33: - | P33: ED-I-Z2000-103 | Q33: - | S33: 1
A34: =A33+1 -> 29 | B34: Z2J18SE3CX | C34: - | D34: ELEVADOR DE CANECAS - Z2J18 | E34: CAIXA DE PROTEÇÃO PARA VIGIA DE VELOCIDADE | F34: - | G34: - | H34: - | I34: - | J34: - | K34: CX. Padrão Vigia de Velocidade com anteparo de 2 Aletas (30 a 60 rpm) | L34: 1 | M34: VOTORANTIM | N34: - | O34: VCM-0828 IT 02 + VCM-0830 | P34: Código de Compra VC: 491550 | Q34: COMPRAR CONFORME MODELO VOTORANTIM INFORMADO NA COLUNA FOLHA DE DADOS | S34: 1
... A38: =A37+1 -> 33 | B38: Z2J18ZSH2 | C38: 571BE02.XS1 | D38: ELEVADOR DE CANECAS - Z2J18 | E38: ESTICAMENTO NO TOPO | F38: SENSOR INDUTIVO DE PROXIMIDADE | G38: 120Vca | H38: - | I38: - | J38: Schneider | K38: XS630B1MAL2 | L38: 1 | M38: SINOMA | N38: Z2RM7 | O38: - | P38: - | Q38: - | S38: 5
A39: =A38+1 -> 34 | B39: Z2J19LSH | C39: - | D39: REGUEIRA DE SAÍDA DA VÁLVULA SEPARADOR - Z2J19 | E39: NÍVEL ALTO | F39: CHAVE DE NÍVEL | G39: 120Vca | H39: 150mm | I39: 300mm | J39: VEGA | K39: VEGAVIB63 | L39: 1 | M39: VOTORANTIM | N39: Z2RM7 | O39: - | P39: ED-I-Z2000-107 | S39: 1
A40: =A39+1 -> 35 | B40: Z2J33SE | C40: 571RF03.SS1 | D40: VÁLVULA ROTATIVA - Z2J33 | E40: VIGIA DE VELOCIDADE | F40: SENSOR INDUTIVO DE PROXIMIDADE | G40: 120Vca | H40: - | I40: - | J40: Schneider | K40: XSAV11801 | L40: 1 | M40: SINOMA | N40: Z2RM3 | O40: - | P40: - | Q40: - | S40: 1
A41: =A40+1 -> 36 | B41: Z2J33SECX | C41: - | D41: VÁLVULA ROTATIVA - Z2J33 | E41: CAIXA DE PROTEÇÃO PARA VIGIA DE VELOCIDADE | F41: - | G41: - | H41: - | I41: - | J41: - | K41: CX. Padrão Vigia de Velocidade com anteparo de 2 Aletas (30 a 60 rpm) | L41: 1 | M41: VOTORANTIM | N41: - | O41: VCM-0828 IT 02 + VCM-0830 | P41: Código de Compra VC: 491550 | Q41: COMPRAR CONFORME MODELO VOTORANTIM INFORMADO NA COLUNA FOLHA DE DADOS | S41: 1
A42: =A41+1 -> 37 | B42: Z2J34SE | C42: 571SC01.SS1 | D42: ROSCA TRANSPORTADORA - Z2J34 | E42: VIGIA DE VELOCIDADE | F42: SENSOR INDUTIVO DE PROXIMIDADE | G42: 120Vca | H42: - | I42: - | J42: Schneider | K42: XSAV11801 | L42: 1 | M42: SINOMA | N42: Z2RM3 | O42: - | P42: - | Q42: - | S42: 1
A43: =A42+1 -> 38 | B43: Z2J34SECX | C43: - | D43: ROSCA TRANSPORTADORA - Z2J34 | E43: CAIXA DE PROTEÇÃO PARA VIGIA DE VELOCIDADE | F43: - | G43: - | H43: - | I43: - | J43: - | K43: CX. Padrão Vigia de Velocidade com anteparo de 2 Aletas (30 a 60 rpm) | L43: 1 | M43: VOTORANTIM | N43: - | O43: VCM-0828 IT 02 + VCM-0830 | P43: Código de Compra VC: 491550 | Q43: COMPRAR CONFORME MODELO VOTORANTIM INFORMADO NA COLUNA FOLHA DE DADOS | S43: 1
...

Sheet TRANSPORTE
H1: CLIENTE: | I1: =CAPA!G27 -> VOTORANTIM CIMENTOS FÁBRICA DE EDEALINA - GO | M1: PROJETO: | N1: =CAPA!A31 -> FÁBRICA DE EDEALINA - GO PROJETO DETALHADO - MOAGEM DE CIMENTO Z2 | Q1: VERIFICADO: | R1: ALEXANDRE MANDUCA
Q2: APROVADO: | R2: GIANCARLO BORGES AVELAR
H3: TÍTULO: | I3: LISTA DE INSTRUMENTO TRANSPORTE DE CIMENTO | M3: Nº. CLIENTE: | N3: =CAPA!J38 -> ED-I-Z2000-120 | Q3: FOLHA: | R3: REVISÃO: | S3: =CAPA!Q24 -> 5
M4: Nº. SM&A: | N4: =CAPA!K19 -> LI-A-20V093E-001 | R4: DATA: | S4: =CAPA!K24 -> 45946
A5: ITEM | B5: TAG VC | C5: TAG SINOMA | D5: EQUIPAMENTO | E5: FUNÇÃO | F5: INSTRUMENTO | G5: TIPO DE SINAL | H5: RANGE MÍNIMO | I5: RANGE MÁXIMO | J5: FABRICANTE | K5: MODELO | L5: QT | M5: FORNECEDOR | N5: PAINEL PARA INTERLIGAÇÃO | O5: MATERIAL PARA MONTAGEM | P5: FOLHA DE DADOS | Q5: COMENTÁRIOS | S5: REV.
A6: 1 | B6: P1P111PSL | C6: 611BF04.PS1 | D6: FILTRO DE MANGAS - P1P111 | E6: PRESSÃO BAIXA LINHA DE AR | F6: PRESSOSTATO | G6: 120Vca | H6: - | I6: - | J6: SCHNEIDER | K6: XML B010A2S11 | L6: 1 | M6: SINOMA | N6: G1RM3/G1RM4 | O6: - | P6: - | Q6: - | S6: 1
A7: =A6+1 -> 2 | B7: P1P111Q1 | C7: 611BF04.UZ1 | D7: FILTRO DE MANGAS - P1P111 | E7: PROGRAMADOR DO FILTRO DE MANGAS | F7: PAINEL LOCAL | G7: 120Vca | H7: - | I7: - | J7: WALSH | K7: WHPC PULSER CONTROLLER | L7: 1 | M7: SINOMA | N7: G1RM3/G1RM4 | O7: - | P7: - | Q7: 3x VÁLVULA SOLENOIDE | S7: 1
A8: =A7+1 -> 3 | B8: P1P111PDT | C8: 611BF04.PZ1 | D8: FILTRO DE MANGAS - P1P111 | E8: PRESSÃO DIFERENCIAL FILTRO DE MANGAS | F8: TRANSMISSOR DE PRESSÃO DIFERENCIAL | G8: 4-20mA | J8: SIEMENS | K8: 7MF0340-1HM01-5SM2-Z B30+D42+E27 | L8: 1 | M8: SINOMA | N8: G1RM3/G1RM4 | O8: - | P8: - | Q8: - | S8: 1
A9: =A8+1 -> 4 | B9: P1P111LSH | C9: 611BF04.LS1 | D9: FILTRO DE MANGAS - P1P111 | E9: NÍVEL ALTO | F9: CHAVE DE NÍVEL | G9: 120Vca | J9: E+H | K9: FTM21-AG242A | L9: 1 | M9: SINOMA | N9: G1RM3/G1RM4 | O9: - | P9: - | Q9: - | S9: 1
A10: =A9+1 -> 5 | B10: P1P113SECX | C10: - | D10: VÁLVULA ROTATIVA - P1P113 | E10: CAIXA DE PROTEÇÃO PARA VIGIA DE VELOCIDADE | F10: - | G10: - | H10: - | I10: - | J10: - | K10: CX. Padrão Vigia de Velocidade com anteparo de 2 Aletas (30 a 60 rpm) | L10: 1 | M10: VOTORANTIM | N10: - | O10: VCM-0828 IT 02 + VCM-0830 | P10: Código de Compra VC: 491550 | Q10: COMPRAR CONFORME MODELO VOTORANTIM INFORMADO NA COLUNA FOLHA DE DADOS | S10: 1
A11: =A10+1 -> 6 | B11: P1P113SE | C11: 611RF03.SS1 | D11: VÁLVULA ROTATIVA - P1P113 | E11: VIGIA DE VELOCIDADE | F11: SENSOR INDUTIVO DE PROXIMIDADE | G11: 120Vca | H11: - | I11: - | J11: SCHNEIDER | K11: TE XSA-V11801 | L11: 1 | M11: SINOMA | N11: G1RM3/G1RM4 | O11: - | P11: - | Q11: - | S11: 1
A12: =A11+1 -> 7 | B12: P1U21LSH | C12: 611BE02.LS1 | D12: ELEVADOR DE CANECAS - P1U21 | E12: NÍVEL ALTO | F12: CHAVE DE NÍVEL | G12: 120Vca | H12: - | I12: - | J12: E+H | K12: FTE20-AA11AA31 | L12: 1 | M12: SINOMA | N12: G1RM5 | O12: - | P12: - | Q12: - | S12: 1
A13: =A12+1 -> 8 | B13: P1U21M2SE | C13: 611BE02.M2.SS1 | D13: ELEVADOR DE CANECAS - P1U21 | E13: SENSOR DO MOTOR AUXILIAR VIGIA DE VELOCIDADE | F13: SENSOR INDUTIVO NAMUR | G13: 120Vca | H13: - | I13: - | J13: PENDENTE SINOMA | K13: IG5497+ECV004 DD0203 | L13: 1 | M13: SINOMA | N13: G1RM3/G1RM4 | O13: - | P13: - | Q13: - | S13: 1
A14: =A13+1 -> 9 | B14: P1U21SE1 | C14: 611BE02.SS1 | D14: ELEVADOR DE CANECAS - P1U21 | E14: SENSOR 1 - PÉ DO ELEVADOR VIGIA DE VELOCIDADE | F14: SENSOR INDUTIVO DE PROXIMIDADE | G14: 120Vca | H14: - | I14: - | J14: Schneider | K14: XSAV11801 | L14: 1 | M14: SINOMA | N14: G1RM5 | O14: - | P14: - | Q14: - | S14: 1
A15: =A14+1 -> 10 | B15: P1U21SE1CX | C15: - | D15: ELEVADOR DE CANECAS - P1U21 | E15: CAIXA DE PROTEÇÃO PARA VIGIA DE VELOCIDADE | F15: - | G15: - | H15: - | I15: - | J15: - | K15: CX. Padrão Vigia de Velocidade com anteparo de 2 Aletas (30 a 60 rpm) | L15: 1 | M15: VOTORANTIM | N15: - | O15: VCM-0828 IT 02 + VCM-0830 | P15: Código de Compra VC: 491550 | Q15: COMPRAR CONFORME MODELO VOTORANTIM INFORMADO NA COLUNA FOLHA DE DADOS | S15: 1
A16: =A15+1 -> 11 | B16: P1U21SE2 | C16: - | D16: ELEVADOR DE CANECAS - P1U21 | E16: SENSOR 2 - PÉ DO ELEVADOR VIGIA DE VELOCIDADE | F16: SENSOR INDUTIVO DE PROXIMIDADE | G16: 120Vca | H16: - | I16: - | J16: TELEMECANIQUE | K16: XS1M30MB250 | L16: 1 | M16: VOTORANTIM | N16: G1RM5 | O16: - | P16: ED-I-Z2000-103 | Q16: - | S16: 1
A17: =A16+1 -> 12 | B17: P1U21SE2CX | C17: - | D17: ELEVADOR DE CANECAS - P1U21 | E17: CAIXA DE PROTEÇÃO PARA VIGIA DE VELOCIDADE | F17: - | G17: - | H17: - | I17: - | J17: - | K17: CX. Padrão Vigia de Velocidade com anteparo de 2 Aletas (30 a 60 rpm) | L17: 1 | M17: VOTORANTIM | N17: - | O17: VCM-0828 IT 02 + VCM-0830 | P17: Código de Compra VC: 491550 | Q17: COMPRAR CONFORME MODELO VOTORANTIM INFORMADO NA COLUNA FOLHA DE DADOS | S17: 1
A18: =A17+1 -> 13 | B18: P1U21SE3 | C18: - | D18: ELEVADOR DE CANECAS - P1U21 | E18: SENSOR - TOPO DO ELEVADOR VIGIA DE VELOCIDADE | F18: SENSOR INDUTIVO DE PROXIMIDADE | G18: 120Vca | H18: - | I18: - | J18: TELEMECANIQUE | K18: XS1M30MB250 | L18: 1 | M18: VOTORANTIM | N18: G1RM3/G1RM4 | O18: - | P18: ED-I-Z2000-103 | Q18: - | S18: 1
A19: =A18+1 -> 14 | B19: P1U21SE3CX | C19: - | D19: ELEVADOR DE CANECAS - P1U21 | E19: CAIXA DE PROTEÇÃO PARA VIGIA DE VELOCIDADE | F19: - | G19: - | H19: - | I19: - | J19: - | K19: CX. Padrão Vigia de Velocidade com anteparo de 2 Aletas (30 a 60 rpm) | L19: 1 | M19: VOTORANTIM | N19: - | O19: VCM-0828 IT 02 + VCM-0830 | P19: Código de Compra VC: 491550 | Q19: COMPRAR CONFORME MODELO VOTORANTIM INFORMADO NA COLUNA FOLHA DE DADOS | S19: 1
A20: =A19+1 -> 15 | B20: P1U21TSH | C20: 611BE02.TS1 | D20: ELEVADOR DE CANECAS - P1U21 | E20: TEMPERATURA ÓLEO ACOPLAMENTO ELEVADOR P1U21 | F20: TERMOSTATO | G20: 120Vca | H20: - | I20: - | J20: Schneider | K20: XCMD2102L1 | L20: 1 | M20: SINOMA | N20: G1RM3/G1RM4 | O20: - | P20: - | Q20: - | S20: 1
A21: =A20+1 -> 16 | B21: P1U21XSH1 | C21: 611BE02.DS1 | D21: ELEVADOR DE CANECAS - P1U21 | E21: DESALINHAMENTO TOPO DO ELEVADOR | F21: SENSOR INDUTIVO DE PROXIMIDADE | G21: 120Vca | H21: - | I21: - | J21: Schneider | K21: XS630B1MAL2 | L21: 2 | M21: SINOMA | N21: G1RM3/G1RM4 | O21: - | P21: - | Q21: P1U21XSH1.1 e P1U21XSH1.2 | S21: 3
... A26: =A25+1 -> 21 | B26: P1U21ZSH2 | C26: 611BE02.XS1 | D26: ELEVADOR DE CANECAS - P1U21 | E26: ESTICAMENTO NO TOPO | F26: SENSOR INDUTIVO DE PROXIMIDADE | G26: 120Vca | H26: - | I26: - | J26: Schneider | K26: XS630B1MAL2 | L26: 1 | M26: SINOMA | N26: G1RM5 | O26: - | P26: - | Q26: - | S26: 5
A27: =A26+1 -> 22 | B27: P1U23LSH1 | D27: REGUEIRA - P1U23 | E27: NÍVEL ALTO 1 | F27: CHAVE DE NÍVEL | G27: 120Vca | H27: 150mm | I27: 300mm | J27: VEGA | K27: VEGAVIB63 | L27: 1 | M27: VOTORANTIM | N27: G1RM3/G1RM4 | O27: - | P27: ED-I-Z2000-107 | Q27: - | S27: 1
A28: =A27+1 -> 23 | B28: P1U23LSH2 | C28: - | D28: REGUEIRA - P1U23 | E28: NÍVEL ALTO 2 | F28: CHAVE DE NÍVEL | G28: 120Vca | H28: 150mm | I28: 300mm | J28: VEGA | K28: VEGAVIB63 | L28: 1 | M28: VOTORANTIM | N28: G1RM3/G1RM4 | O28: - | P28: ED-I-Z2000-107 | Q28: - | S28: 1
A29: =A28+1 -> 24 | B29: P1U23LSH3 | C29: - | D29: REGUEIRA - P1U23 | E29: NÍVEL ALTO 3 | F29: CHAVE DE NÍVEL | G29: 120Vca | H29: 150mm | I29: 300mm | J29: VEGA | K29: VEGAVIB63 | L29: 1 | M29: VOTORANTIM | N29: G1RM3/G1RM4 | O29: - | P29: ED-I-Z2000-107 | Q29: - | S29: 1
A30: =A29+1 -> 25 | B30: P1U23LSH4 | C30: - | D30: REGUEIRA - P1U23 | E30: NÍVEL ALTO 4 | F30: CHAVE DE NÍVEL | G30: 120Vca | H30: 150mm | I30: 300mm | J30: VEGA | K30: VEGAVIB63 | L30: 1 | M30: VOTORANTIM | N30: G1RM3/G1RM4 | O30: - | P30: ED-I-Z2000-107 | Q30: - | S30: 1
A31: =A30+1 -> 26 | B31: P1U23LSH5 | C31: - | D31: REGUEIRA - P1U23 | E31: NÍVEL ALTO 5 | F31: CHAVE DE NÍVEL | G31: 120Vca | H31: 150mm | I31: 300mm | J31: VEGA | K31: VEGAVIB63 | L31: 1 | M31: VOTORANTIM | N31: G1RM3/G1RM4 | O31: - | P31: ED-I-Z2000-107 | Q31: - | S31: 1
A32: =A31+1 -> 27 | B32: P1U23LSH6 | C32: - | D32: REGUEIRA - P1U23 | E32: NÍVEL ALTO 6 | F32: CHAVE DE NÍVEL | G32: 120Vca | H32: 150mm | I32: 300mm | J32: VEGA | K32: VEGAVIB63 | L32: 1 | M32: VOTORANTIM | N32: G1RM3/G1RM4 | O32: - | P32: ED-I-Z2000-107 | Q32: - | S32: 1
A33: =A32+1 -> 28 | B33: P1U24XV1 | C33: - | D33: VÁLVULA DE DESVIO - P1U24 REGUEIRA - P1U23 | E33: ABRE | F33: SOLENOIDE | G33: 120Vca | H33: - | I33: - | J33: FESTO | K33: MFH-5/2-D-3-C DSBG-V160-400-PPVA-N3 | L33: 1 | M33: SINOMA | N33: G1RM3/G1RM4 | O33: - | P33: - | Q33: - | S33: 1
A34: =A33+1 -> 29 | B34: P1U24XV2 | C34: - | D34: VÁLVULA DE DESVIO - P1U24 REGUEIRA - P1U23 | E34: FECHA | F34: SOLENOIDE | G34: 120Vca | H34: - | I34: - | O34: - | P34: - | Q34: - | S34: 1
A35: =A34+1 -> 30 | B35: P1U24ZSH | C35: 611MD01.ZS1 | D35: VÁLVULA DE DESVIO - P1U24 REGUEIRA - P1U23 | E35: POSIÇÃO ABERTA | F35: FIM DE CURSO | G35: 120Vca | H35: - | I35: - | J35: Schneider | K35: XS630B1MAL2 | L35: 1 | M35: SINOMA | N35: G1RM3/G1RM4 | O35: - | P35: - | Q35: - | S35: 1
A36: =A35+1 -> 31 | B36: P1U24ZSL | C36: 611MD01.ZS2 | D36: VÁLVULA DE DESVIO - P1U24 REGUEIRA - P1U23 | E36: POSIÇÃO FECHADA | F36: FIM DE CURSO | G36: 120Vca | H36: - | I36: - | J36: Schneider | K36: XS630B1MAL2 | L36: 1 | M36: SINOMA | N36: G1RM3/G1RM4 | O36: - | P36: - | Q36: - | S36: 1
A37: =A36+1 -> 32 | B37: P1U25XV1 | C37: - | D37: VÁLVULA DE DESVIO - P1U25 REGUEIRA - P1U23 | E37: ABRE | F37: SOLENOIDE | G37: 120Vca | H37: - | I37: - | J37: FESTO | K37: MFH-5/2-D-3-C DSBG-V160-400-PPVA-N3 | L37: 1 | M37: SINOMA | N37: G1RM3/G1RM4 | O37: - | P37: - | Q37: - | S37: 1
A38: =A37+1 -> 33 | B38: P1U25XV2 | C38: - | D38: VÁLVULA DE DESVIO - P1U25 REGUEIRA - P1U23 | E38: FECHA | F38: SOLENOIDE | G38: 120Vca | H38: - | I38: - | O38: - | P38: - | Q38: - | S38: 1
A39: =A38+1 -> 34 | B39: P1U25ZSH | C39: 611MD02.ZS1 | D39: VÁLVULA DE DESVIO - P1U25 REGUEIRA - P1U23 | E39: POSIÇÃO ABERTA | F39: FIM DE CURSO | G39: 120Vca | H39: - | I39: - | J39: Schneider | K39: XS630B1MAL2 | L39: 1 | M39: SINOMA | N39: G1RM3/G1RM4 | O39: - | P39: - | Q39: - | S39: 1
A40: =A39+1 -> 35 | B40: P1U25ZSL | C40: 611MD02.ZS2 | D40: VÁLVULA DE DESVIO - P1U25 REGUEIRA - P1U23 | E40: POSIÇÃO FECHADA | F40: FIM DE CURSO | G40: 120Vca | H40: - | I40: - | J40: Schneider | K40: XS630B1MAL2 | L40: 1 | M40: SINOMA | N40: G1RM3/G1RM4 | O40: - | P40: - | Q40: - | S40: 1
A41: =A40+1 -> 36 | B41: P1U26XV1 | C41: - | D41: VÁLVULA DE DESVIO - P1U26 REGUEIRA - P1U23 | E41: ABRE | F41: SOLENOIDE | G41: 120Vca | H41: - | I41: - | J41: FESTO | K41: MFH-5/2-D-3-C DSBG-V160-400-PPVA-N3 | L41: 1 | M41: SINOMA | N41: G1RM3/G1RM4 | O41: - | P41: - | Q41: - | S41: 1
A42: =A41+1 -> 37 | B42: P1U26XV2 | C42: - | D42: VÁLVULA DE DESVIO - P1U26 REGUEIRA - P1U23 | E42: FECHA | F42: SOLENOIDE | G42: 120Vca | H42: - | I42: - | O42: - | P42: - | Q42: - | S42: 1
A43: =A42+1 -> 38 | B43: P1U26ZSH | C43: 611MD03.ZS1 | D43: VÁLVULA DE DESVIO - P1U26 REGUEIRA - P1U23 | E43: POSIÇÃO ABERTA | F43: FIM DE CURSO | G43: 120Vca | H43: - | I43: - | J43: Schneider | K43: XS630B1MAL2 | L43: 1 | M43: SINOMA | N43: G1RM3/G1RM4 | O43: - | P43: - | Q43: - | S43: 1
A44: =A43+1 -> 39 | B44: P1U26ZSL | C44: 611MD03.ZS2 | D44: VÁLVULA DE DESVIO - P1U26 REGUEIRA - P1U23 | E44: POSIÇÃO FECHADA | F44: FIM DE CURSO | G44: 120Vca | H44: - | I44: - | J44: Schneider | K44: XS630B1MAL2 | L44: 1 | M44: SINOMA | N44: G1RM3/G1RM4 | O44: - | P44: - | Q44: - | S44: 1
...
